Workbook

Sheet Users
A1: Id | B1: "EmployeeId" | C1: "FirstName" | D1: "LastName" | E1: "Signature" | F1: "IsPartTime" | G1: "UserName" | H1: "NormalizedUserName" | I1: "Email" | J1: "NormalizedEmail" | K1: "EmailConfirmed" | L1: "PasswordHash" | M1: "SecurityStamp" | N1: "ConcurrencyStamp" | O1: "PhoneNumber" | P1: "PhoneNumberConfirmed" | Q1: "TwoFactorEnabled" | R1: "LockoutEnd" | S1: "LockoutEnabled" | T1: "AccessFailedCount") | V1: gen
A2: 4dbc7800-d343-4d6e-ab27-a7706b0cd126 | B2: NULL | C2: อัลบัส | D2: ดัมเบิลดอร์ | E2: NULL | F2: FALSE | G2: ab01 | H2: AB01 | I2: AlbusDumbledore@hw.com | J2: NULL | K2: FALSE | L2: AQAAAAEAACcQAAAAEGEZl8LrZ8xv31BTdWZ+mtvxkRDq2XHbjXphN44J+/QjS9MKKvTc0c+ieaG9C4NBTg== | M2: 5F6FHQGLKMHYTFQLDDCIDTITVVTNNGVX | N2: 0dc239e5-41eb-4767-bbf4-aff5a0617e2f | O2: NULL | P2: FALSE | Q2: FALSE | R2: NULL | S2: TRUE | T2: 0 | V2: =_xlfn.CONCAT("('",Users!A2,"','",C2,"','",D2,"',",F2,",'",G2,"','",H2,"',",K2,",'",L2,"','",M2,"','",N2,"',",P2,",",Q2,",",S2,",",T2,"),") -> ('4dbc7800-d343-4d6e-ab27-a7706b0cd126','อัลบัส','ดัมเบิลดอร์',FALSE,'ab01','AB01',FALSE,'AQAAAAEAACcQAAAAEGEZl8LrZ8xv31BTdWZ+mtvxkRDq2XHbjXphN44J+/QjS9MKKvTc0c+ieaG9C4NBTg==','5F6FHQGLKMHYTFQLDDCIDTITVVTNNGVX','0dc239e5-41eb-4767-bbf4-aff5a0617e2f',FALSE,FALSE,TRUE,0),
A3: ee7268d6-3012-4918-ad50-df59ac091c9d | B3: NULL | C3: มิเนอร์ว่า | D3: มักกอนนากัล | E3: NULL | F3: FALSE | G3: mm02 | H3: MM02 | I3: MinervaMcGonagall@hw.com | J3: NULL | K3: FALSE | L3: AQAAAAEAACcQAAAAECLgwpQBrwoMBrr9nWwzagGyGzRAj0KLbjTIYZgidQ1bmGFGTq1tZbOIlA9gc8vvrQ== | M3: X6NMOGQCLAIU2MNAUBF6JL7MDIMRMLEI | N3: 932124df-b3f0-4af3-bc5a-ff59a6165196 | O3: NULL | P3: FALSE | Q3: FALSE | R3: NULL | S3: TRUE | T3: 0 | V3: =_xlfn.CONCAT("('",Users!A3,"','",C3,"','",D3,"',",F3,",'",G3,"','",H3,"',",K3,",'",L3,"','",M3,"','",N3,"',",P3,",",Q3,",",S3,",",T3,"),") -> ('ee7268d6-3012-4918-ad50-df59ac091c9d','มิเนอร์ว่า','มักกอนนากัล',FALSE,'mm02','MM02',FALSE,'AQAAAAEAACcQAAAAECLgwpQBrwoMBrr9nWwzagGyGzRAj0KLbjTIYZgidQ1bmGFGTq1tZbOIlA9gc8vvrQ==','X6NMOGQCLAIU2MNAUBF6JL7MDIMRMLEI','932124df-b3f0-4af3-bc5a-ff59a6165196',FALSE,FALSE,TRUE,0),
A4: 258a7d9f-5fa7-4eae-8d31-bb7f64d35a79 | B4: NULL | C4: เซเวอรัส | D4: สเนป | E4: NULL | F4: FALSE | G4: ss03 | H4: SS03 | I4: SeverusSnape@hw.com | J4: NULL | K4: FALSE | L4: AQAAAAEAACcQAAAAEDvIyA3NZIWUkhnOuDJm2BF8i6yZQaI3wQBk6anHwe/zbWorI9sqbXa3lHdE9slJiA== | M4: YE5UAFKK47JOJQHX7O6B2AJDPWCCUBKY | N4: e2dee0f0-defb-47d4-bfb1-6b9d4ad148ce | O4: NULL | P4: FALSE | Q4: FALSE | R4: NULL | S4: TRUE | T4: 0 | V4: =_xlfn.CONCAT("('",Users!A4,"','",C4,"','",D4,"',",F4,",'",G4,"','",H4,"',",K4,",'",L4,"','",M4,"','",N4,"',",P4,",",Q4,",",S4,",",T4,"),") -> ('258a7d9f-5fa7-4eae-8d31-bb7f64d35a79','เซเวอรัส','สเนป',FALSE,'ss03','SS03',FALSE,'AQAAAAEAACcQAAAAEDvIyA3NZIWUkhnOuDJm2BF8i6yZQaI3wQBk6anHwe/zbWorI9sqbXa3lHdE9slJiA==','YE5UAFKK47JOJQHX7O6B2AJDPWCCUBKY','e2dee0f0-defb-47d4-bfb1-6b9d4ad148ce',FALSE,FALSE,TRUE,0),
A5: 4875d3e5-9a6d-41c5-b3d5-7b4359c1baad | B5: NULL | C5: รูเบอัส | D5: แฮกริด | E5: NULL | F5: FALSE | G5: rh04 | H5: RH04 | I5: RubeusHagrid@hw.com | J5: NULL | K5: FALSE | L5: AQAAAAEAACcQAAAAEDhiJSuDkGzdWrq402YkvxcwBxE3jeEZdK6SXGrk8TR0Phwns7ebXrT8pNbl093vwQ== | M5: BH5B6OVVFSHLRXMHBMSZQ77S53ZROUTF | N5: 14cb475e-6963-4546-bfa2-e2bab482003b | O5: NULL | P5: FALSE | Q5: FALSE | R5: NULL | S5: TRUE | T5: 0 | V5: =_xlfn.CONCAT("('",Users!A5,"','",C5,"','",D5,"',",F5,",'",G5,"','",H5,"',",K5,",'",L5,"','",M5,"','",N5,"',",P5,",",Q5,",",S5,",",T5,"),") -> ('4875d3e5-9a6d-41c5-b3d5-7b4359c1baad','รูเบอัส','แฮกริด',FALSE,'rh04','RH04',FALSE,'AQAAAAEAACcQAAAAEDhiJSuDkGzdWrq402YkvxcwBxE3jeEZdK6SXGrk8TR0Phwns7ebXrT8pNbl093vwQ==','BH5B6OVVFSHLRXMHBMSZQ77S53ZROUTF','14cb475e-6963-4546-bfa2-e2bab482003b',FALSE,FALSE,TRUE,0),
A6: 832bd9bf-6d52-4261-8eb0-80c3ca1fa1dd | B6: NULL | C6: รีมัส | D6: ลูปิน | E6: NULL | F6: FALSE | G6: rl05 | H6: RL05 | I6: RemusLupin@hw.com | J6: NULL | K6: FALSE | L6: AQAAAAEAACcQAAAAEFhXCj4OhvYhIHWQ/0eh93zUCtMwGByiZ0OAqb7edQmpGvW2fP9i5ErcH5F/56w9rA== | M6: KUDFRXGYWA4BQNEJ5PSEPUWZXZWXB2Z5 | N6: fad281eb-5f47-43bd-b214-7102b2426675 | O6: NULL | P6: FALSE | Q6: FALSE | R6: NULL | S6: TRUE | T6: 0 | V6: =_xlfn.CONCAT("('",Users!A6,"','",C6,"','",D6,"',",F6,",'",G6,"','",H6,"',",K6,",'",L6,"','",M6,"','",N6,"',",P6,",",Q6,",",S6,",",T6,"),") -> ('832bd9bf-6d52-4261-8eb0-80c3ca1fa1dd','รีมัส','ลูปิน',FALSE,'rl05','RL05',FALSE,'AQAAAAEAACcQAAAAEFhXCj4OhvYhIHWQ/0eh93zUCtMwGByiZ0OAqb7edQmpGvW2fP9i5ErcH5F/56w9rA==','KUDFRXGYWA4BQNEJ5PSEPUWZXZWXB2Z5','fad281eb-5f47-43bd-b214-7102b2426675',FALSE,FALSE,TRUE,0),
A7: 8090c38f-ca53-4238-810d-811a59e6cc68 | B7: NULL | C7: ซิเรียส | D7: แบล็ก | E7: NULL | F7: FALSE | G7: sb06 | H7: SB06 | I7: SiriusBlack@hw.com | J7: NULL | K7: FALSE | L7: AQAAAAEAACcQAAAAEMXe/8qIMEM1DjwKMefYOL29ox39u8ELM6Zw5T9tX0fIW0wOSnLlAlqnfx7VNUekYg== | M7: TTIVS7Z4ZY64UJCV5EVGFKFMCQVLL54V | N7: b8c47777-cca3-4df1-86be-d8aab8abf878 | O7: NULL | P7: FALSE | Q7: FALSE | R7: NULL | S7: TRUE | T7: 0 | V7: =_xlfn.CONCAT("('",Users!A7,"','",C7,"','",D7,"',",F7,",'",G7,"','",H7,"',",K7,",'",L7,"','",M7,"','",N7,"',",P7,",",Q7,",",S7,",",T7,"),") -> ('8090c38f-ca53-4238-810d-811a59e6cc68','ซิเรียส','แบล็ก',FALSE,'sb06','SB06',FALSE,'AQAAAAEAACcQAAAAEMXe/8qIMEM1DjwKMefYOL29ox39u8ELM6Zw5T9tX0fIW0wOSnLlAlqnfx7VNUekYg==','TTIVS7Z4ZY64UJCV5EVGFKFMCQVLL54V','b8c47777-cca3-4df1-86be-d8aab8abf878',FALSE,FALSE,TRUE,0),
A8: 83ae307c-cd8c-4564-b0e8-da8d0b3f63fc | B8: NULL | C8: กิลเดอรอย | D8: ล็อกฮาร์ต | E8: NULL | F8: FALSE | G8: gl07 | H8: GL07 | I8: GilderoyLockhart@hw.com | J8: NULL | K8: FALSE | L8: AQAAAAEAACcQAAAAEDcF3kZIljQnnDnS8RaIiSv/+5dedc4T8g673HEY+ITjvgpSX82KvRN//XfKtekjgA== | M8: QESSQCWHP6TGCQXSWOF6WMDHPX7Y2TPY | N8: 5c6b9f0b-a0e6-4b0d-914e-b1333e4bb8c3 | O8: NULL | P8: FALSE | Q8: FALSE | R8: NULL | S8: TRUE | T8: 0 | V8: =_xlfn.CONCAT("('",Users!A8,"','",C8,"','",D8,"',",F8,",'",G8,"','",H8,"',",K8,",'",L8,"','",M8,"','",N8,"',",P8,",",Q8,",",S8,",",T8,"),") -> ('83ae307c-cd8c-4564-b0e8-da8d0b3f63fc','กิลเดอรอย','ล็อกฮาร์ต',FALSE,'gl07','GL07',FALSE,'AQAAAAEAACcQAAAAEDcF3kZIljQnnDnS8RaIiSv/+5dedc4T8g673HEY+ITjvgpSX82KvRN//XfKtekjgA==','QESSQCWHP6TGCQXSWOF6WMDHPX7Y2TPY','5c6b9f0b-a0e6-4b0d-914e-b1333e4bb8c3',FALSE,FALSE,TRUE,0),
A9: ca5037bc-1ffb-4fcb-a5d0-495c3cd5aa99 | B9: NULL | C9: ฮอเรซ | D9: สลักฮอร์น | E9: NULL | F9: FALSE | G9: hs08 | H9: HS08 | I9: HoraceSlughorn@hw.com | J9: NULL | K9: FALSE | L9: AQAAAAEAACcQAAAAEOZOlp1yRVcUqC0pT8anNRMTnvOBDAF2YMV+uz56NJrTibFtqBHoITi0oxo4P93zcQ== | M9: 6R5LOQYAFZRGPJVRDIGJPMGGI5NLIDDG | N9: 9ff6eac9-6ec0-483a-be33-d1c8633b715e | O9: NULL | P9: FALSE | Q9: FALSE | R9: NULL | S9: TRUE | T9: 0 | V9: =_xlfn.CONCAT("('",Users!A9,"','",C9,"','",D9,"',",F9,",'",G9,"','",H9,"',",K9,",'",L9,"','",M9,"','",N9,"',",P9,",",Q9,",",S9,",",T9,"),") -> ('ca5037bc-1ffb-4fcb-a5d0-495c3cd5aa99','ฮอเรซ','สลักฮอร์น',FALSE,'hs08','HS08',FALSE,'AQAAAAEAACcQAAAAEOZOlp1yRVcUqC0pT8anNRMTnvOBDAF2YMV+uz56NJrTibFtqBHoITi0oxo4P93zcQ==','6R5LOQYAFZRGPJVRDIGJPMGGI5NLIDDG','9ff6eac9-6ec0-483a-be33-d1c8633b715e',FALSE,FALSE,TRUE,0),
A10: 6ac9ae0c-53d1-497e-9e7d-3ce976d1f0d8 | B10: NULL | C10: ซิบิลล์ | D10: ทรีลอว์นีย์ | E10: NULL | F10: FALSE | G10: st09 | H10: ST09 | I10: SybillTrelawney@hw.com | J10: NULL | K10: FALSE | L10: AQAAAAEAACcQAAAAEEFVAKyjlgAIUTKz7rbdXJIq9lLHZFlvWkBA6vRLKZZ14pxzXUS8RJibsWdhXas4Aw== | M10: 4OWG4FC2VJ7BTD6CPPFPI2G3PX7RLB7Y | N10: b7e078db-6073-46f6-bed8-a85454816e2c | O10: NULL | P10: FALSE | Q10: FALSE | R10: NULL | S10: TRUE | T10: 0 | V10: =_xlfn.CONCAT("('",Users!A10,"','",C10,"','",D10,"',",F10,",'",G10,"','",H10,"',",K10,",'",L10,"','",M10,"','",N10,"',",P10,",",Q10,",",S10,",",T10,"),") -> ('6ac9ae0c-53d1-497e-9e7d-3ce976d1f0d8','ซิบิลล์','ทรีลอว์นีย์',FALSE,'st09','ST09',FALSE,'AQAAAAEAACcQAAAAEEFVAKyjlgAIUTKz7rbdXJIq9lLHZFlvWkBA6vRLKZZ14pxzXUS8RJibsWdhXas4Aw==','4OWG4FC2VJ7BTD6CPPFPI2G3PX7RLB7Y','b7e078db-6073-46f6-bed8-a85454816e2c',FALSE,FALSE,TRUE,0),
A11: eb8ed330-f3ab-4966-993c-2245653e075e | B11: NULL | C11: ฟีลิอุส | D11: ฟลิตวิก | E11: NULL | F11: FALSE | G11: ff10 | H11: FF10 | I11: FiliusFlitwick@hw.com | J11: NULL | K11: FALSE | L11: AQAAAAEAACcQAAAAEDcF3kZIljQnnDnS8RaIiSv/+5dedc4T8g673HEY+ITjvgpSX82KvRN//XfKtekjgA== | M11: QESSQCWHP6TGCQXSWOF6WMDHPX7Y2TPY | N11: 5c6b9f0b-a0e6-4b0d-914e-b1333e4bb8c3 | O11: NULL | P11: FALSE | Q11: FALSE | R11: NULL | S11: TRUE | T11: 0 | V11: =_xlfn.CONCAT("('",Users!A11,"','",C11,"','",D11,"',",F11,",'",G11,"','",H11,"',",K11,",'",L11,"','",M11,"','",N11,"',",P11,",",Q11,",",S11,",",T11,"),") -> ('eb8ed330-f3ab-4966-993c-2245653e075e','ฟีลิอุส','ฟลิตวิก',FALSE,'ff10','FF10',FALSE,'AQAAAAEAACcQAAAAEDcF3kZIljQnnDnS8RaIiSv/+5dedc4T8g673HEY+ITjvgpSX82KvRN//XfKtekjgA==','QESSQCWHP6TGCQXSWOF6WMDHPX7Y2TPY','5c6b9f0b-a0e6-4b0d-914e-b1333e4bb8c3',FALSE,FALSE,TRUE,0),
A12: ee44cb44-8886-4193-9a02-53fdad80e46e | B12: NULL | C12: อาร์กัส | D12: ฟิลช์ | E12: NULL | F12: FALSE | G12: af11 | H12: AF11 | I12: ArgusFilch@hw.com | J12: NULL | K12: FALSE | L12: AQAAAAEAACcQAAAAEOZOlp1yRVcUqC0pT8anNRMTnvOBDAF2YMV+uz56NJrTibFtqBHoITi0oxo4P93zcQ== | M12: 6R5LOQYAFZRGPJVRDIGJPMGGI5NLIDDG | N12: 9ff6eac9-6ec0-483a-be33-d1c8633b715e | O12: NULL | P12: FALSE | Q12: FALSE | R12: NULL | S12: TRUE | T12: 0 | V12: =_xlfn.CONCAT("('",Users!A12,"','",C12,"','",D12,"',",F12,",'",G12,"','",H12,"',",K12,",'",L12,"','",M12,"','",N12,"',",P12,",",Q12,",",S12,",",T12,"),") -> ('ee44cb44-8886-4193-9a02-53fdad80e46e','อาร์กัส','ฟิลช์',FALSE,'af11','AF11',FALSE,'AQAAAAEAACcQAAAAEOZOlp1yRVcUqC0pT8anNRMTnvOBDAF2YMV+uz56NJrTibFtqBHoITi0oxo4P93zcQ==','6R5LOQYAFZRGPJVRDIGJPMGGI5NLIDDG','9ff6eac9-6ec0-483a-be33-d1c8633b715e',FALSE,FALSE,TRUE,0),
A13: 7d26cfab-fb31-41cc-a4ea-29e610568be3 | B13: NULL | C13: มาดาม | D13: พอมฟรีย์ | E13: NULL | F13: FALSE | G13: mp12 | H13: MP12 | I13: MadamPomfrey@hw.com | J13: NULL | K13: FALSE | L13: AQAAAAEAACcQAAAAEEFVAKyjlgAIUTKz7rbdXJIq9lLHZFlvWkBA6vRLKZZ14pxzXUS8RJibsWdhXas4Aw== | M13: 4OWG4FC2VJ7BTD6CPPFPI2G3PX7RLB7Y | N13: b7e078db-6073-46f6-bed8-a85454816e2c | O13: NULL | P13: FALSE | Q13: FALSE | R13: NULL | S13: TRUE | T13: 0 | V13: =_xlfn.CONCAT("('",Users!A13,"','",C13,"','",D13,"',",F13,",'",G13,"','",H13,"',",K13,",'",L13,"','",M13,"','",N13,"',",P13,",",Q13,",",S13,",",T13,");") -> ('7d26cfab-fb31-41cc-a4ea-29e610568be3','มาดาม','พอมฟรีย์',FALSE,'mp12','MP12',FALSE,'AQAAAAEAACcQAAAAEEFVAKyjlgAIUTKz7rbdXJIq9lLHZFlvWkBA6vRLKZZ14pxzXUS8RJibsWdhXas4Aw==','4OWG4FC2VJ7BTD6CPPFPI2G3PX7RLB7Y','b7e078db-6073-46f6-bed8-a85454816e2c',FALSE,FALSE,TRUE,0);

Sheet VAlue_UserRole
B1: userId | C1: RoleId
A2: AlbusDumbledore@hw.com | B2: 4dbc7800-d343-4d6e-ab27-a7706b0cd126 | C2: baad21b1-6d08-4823-8cf3-0776a6266488 | D2: =_xlfn.CONCAT("('",B2,"','",C2,"'),") -> ('4dbc7800-d343-4d6e-ab27-a7706b0cd126','baad21b1-6d08-4823-8cf3-0776a6266488'),
A3: MinervaMcGonagall@hw.com | B3: ee7268d6-3012-4918-ad50-df59ac091c9d | C3: baad21b1-6d08-4823-8cf3-0776a6266488 | D3: =_xlfn.CONCAT("('",B3,"','",C3,"'),") -> ('ee7268d6-3012-4918-ad50-df59ac091c9d','baad21b1-6d08-4823-8cf3-0776a6266488'),
A4: SeverusSnape@hw.com | B4: 258a7d9f-5fa7-4eae-8d31-bb7f64d35a79 | C4: 9453a296-a401-a345-bf81-bca7ab0f73b5 | D4: =_xlfn.CONCAT("('",B4,"','",C4,"'),") -> ('258a7d9f-5fa7-4eae-8d31-bb7f64d35a79','9453a296-a401-a345-bf81-bca7ab0f73b5'),
A5: RubeusHagrid@hw.com | B5: 4875d3e5-9a6d-41c5-b3d5-7b4359c1baad | C5: 9453a296-a401-a345-bf81-bca7ab0f73b5 | D5: =_xlfn.CONCAT("('",B5,"','",C5,"'),") -> ('4875d3e5-9a6d-41c5-b3d5-7b4359c1baad','9453a296-a401-a345-bf81-bca7ab0f73b5'),
A6: RemusLupin@hw.com | B6: 832bd9bf-6d52-4261-8eb0-80c3ca1fa1dd | C6: 9453a296-a401-72a7-bf81-bca7ab0fa401 | D6: =_xlfn.CONCAT("('",B6,"','",C6,"'),") -> ('832bd9bf-6d52-4261-8eb0-80c3ca1fa1dd','9453a296-a401-72a7-bf81-bca7ab0fa401'),
A7: SiriusBlack@hw.com | B7: 8090c38f-ca53-4238-810d-811a59e6cc68 | C7: 9453a296-a401-72a7-bf81-bca7ab0fa401 | D7: =_xlfn.CONCAT("('",B7,"','",C7,"'),") -> ('8090c38f-ca53-4238-810d-811a59e6cc68','9453a296-a401-72a7-bf81-bca7ab0fa401'),
A8: GilderoyLockhart@hw.com | B8: 83ae307c-cd8c-4564-b0e8-da8d0b3f63fc | C8: a7c93a18-5c50-4e28-b02d-3b50cc3e17f1 | D8: =_xlfn.CONCAT("('",B8,"','",C8,"'),") -> ('83ae307c-cd8c-4564-b0e8-da8d0b3f63fc','a7c93a18-5c50-4e28-b02d-3b50cc3e17f1'),
A9: HoraceSlughorn@hw.com | B9: ca5037bc-1ffb-4fcb-a5d0-495c3cd5aa99 | C9: a7c93a18-5c50-4e28-b02d-3b50cc3e17f1 | D9: =_xlfn.CONCAT("('",B9,"','",C9,"'),") -> ('ca5037bc-1ffb-4fcb-a5d0-495c3cd5aa99','a7c93a18-5c50-4e28-b02d-3b50cc3e17f1'),
A10: SybillTrelawney@hw.com | B10: 6ac9ae0c-53d1-497e-9e7d-3ce976d1f0d8 | C10: f903d36f-2531-4916-86bb-7b051aac7029 | D10: =_xlfn.CONCAT("('",B10,"','",C10,"'),") -> ('6ac9ae0c-53d1-497e-9e7d-3ce976d1f0d8','f903d36f-2531-4916-86bb-7b051aac7029'),
A11: FiliusFlitwick@hw.com | B11: eb8ed330-f3ab-4966-993c-2245653e075e | C11: f903d36f-2531-4916-86bb-7b051aac7029 | D11: =_xlfn.CONCAT("('",B11,"','",C11,"'),") -> ('eb8ed330-f3ab-4966-993c-2245653e075e','f903d36f-2531-4916-86bb-7b051aac7029'),
A12: ArgusFilch@hw.com | B12: ee44cb44-8886-4193-9a02-53fdad80e46e | C12: 9453a296-a401-480b-bf81-bca7ab0f72a7 | D12: =_xlfn.CONCAT("('",B12,"','",C12,"'),") -> ('ee44cb44-8886-4193-9a02-53fdad80e46e','9453a296-a401-480b-bf81-bca7ab0f72a7'),
A13: MadamPomfrey@hw.com | B13: 7d26cfab-fb31-41cc-a4ea-29e610568be3 | C13: 9453a296-a401-480b-bf81-bca7ab0f72a7 | D13: =_xlfn.CONCAT("('",B13,"','",C13,"');") -> ('7d26cfab-fb31-41cc-a4ea-29e610568be3','9453a296-a401-480b-bf81-bca7ab0f72a7');

Sheet Value_UserUnit
A2: 4dbc7800-d343-4d6e-ab27-a7706b0cd126 | B2: -1 | C2: =_xlfn.CONCAT("('",A2,"',",B2,"),") -> ('4dbc7800-d343-4d6e-ab27-a7706b0cd126',-1),
A3: ee7268d6-3012-4918-ad50-df59ac091c9d | B3: -1 | C3: =_xlfn.CONCAT("('",A3,"',",B3,"),") -> ('ee7268d6-3012-4918-ad50-df59ac091c9d',-1),
A4: 258a7d9f-5fa7-4eae-8d31-bb7f64d35a79 | B4: -1 | C4: =_xlfn.CONCAT("('",A4,"',",B4,"),") -> ('258a7d9f-5fa7-4eae-8d31-bb7f64d35a79',-1),
A5: 4875d3e5-9a6d-41c5-b3d5-7b4359c1baad | B5: -1 | C5: =_xlfn.CONCAT("('",A5,"',",B5,"),") -> ('4875d3e5-9a6d-41c5-b3d5-7b4359c1baad',-1),
A6: 832bd9bf-6d52-4261-8eb0-80c3ca1fa1dd | B6: -1 | C6: =_xlfn.CONCAT("('",A6,"',",B6,"),") -> ('832bd9bf-6d52-4261-8eb0-80c3ca1fa1dd',-1),
A7: 8090c38f-ca53-4238-810d-811a59e6cc68 | B7: -1 | C7: =_xlfn.CONCAT("('",A7,"',",B7,"),") -> ('8090c38f-ca53-4238-810d-811a59e6cc68',-1),
A8: 83ae307c-cd8c-4564-b0e8-da8d0b3f63fc | B8: -1 | C8: =_xlfn.CONCAT("('",A8,"',",B8,"),") -> ('83ae307c-cd8c-4564-b0e8-da8d0b3f63fc',-1),
A9: ca5037bc-1ffb-4fcb-a5d0-495c3cd5aa99 | B9: -1 | C9: =_xlfn.CONCAT("('",A9,"',",B9,"),") -> ('ca5037bc-1ffb-4fcb-a5d0-495c3cd5aa99',-1),
A10: 6ac9ae0c-53d1-497e-9e7d-3ce976d1f0d8 | B10: -1 | C10: =_xlfn.CONCAT("('",A10,"',",B10,"),") -> ('6ac9ae0c-53d1-497e-9e7d-3ce976d1f0d8',-1),
A11: eb8ed330-f3ab-4966-993c-2245653e075e | B11: -1 | C11: =_xlfn.CONCAT("('",A11,"',",B11,"),") -> ('eb8ed330-f3ab-4966-993c-2245653e075e',-1),
A12: ee44cb44-8886-4193-9a02-53fdad80e46e | B12: -1 | C12: =_xlfn.CONCAT("('",A12,"',",B12,"),") -> ('ee44cb44-8886-4193-9a02-53fdad80e46e',-1),
A13: 7d26cfab-fb31-41cc-a4ea-29e610568be3 | B13: -1 | C13: =_xlfn.CONCAT("('",A13,"',",B13,");") -> ('7d26cfab-fb31-41cc-a4ea-29e610568be3',-1);

Sheet Value_Incomes
A2: 0f171fd4-1e5a-4e61-b255-0eff804cf6be | B2: 2025-03-13 06:44:05.251356+00 | C2: 866dabc4-6501-44d2-a0e5-65da9c45a46e | D2: 2025-03-13 06:44:05.251356+00 | E2: 866dabc4-6501-44d2-a0e5-65da9c45a46e | F2: TRUE | G2: 0 | H2: UserIncome | J2: 4dbc7800-d343-4d6e-ab27-a7706b0cd126 | K2: 200 | N2: 2 | O2: 0 | P2: =_xlfn.CONCAT("('",A2,"','",B2,"','",C2,"','",D2,"','",E2,"',",F2,",",G2,",'",H2,"','",J2,"',",K2,",",N2,",",O2,"),") -> ('0f171fd4-1e5a-4e61-b255-0eff804cf6be','2025-03-13 06:44:05.251356+00','866dabc4-6501-44d2-a0e5-65da9c45a46e','2025-03-13 06:44:05.251356+00','866dabc4-6501-44d2-a0e5-65da9c45a46e',TRUE,0,'UserIncome','4dbc7800-d343-4d6e-ab27-a7706b0cd126',200,2,0),
A3: 1a7f70e8-f02d-485e-aa9a-42bb5c4073d5 | B3: 2025-03-13 06:44:12.673942+00 | C3: 866dabc4-6501-44d2-a0e5-65da9c45a46e | D3: 2025-03-13 06:44:12.673942+00 | E3: 866dabc4-6501-44d2-a0e5-65da9c45a46e | F3: TRUE | G3: 0 | H3: UserIncome | J3: ee7268d6-3012-4918-ad50-df59ac091c9d | K3: 250 | N3: 2 | O3: 0 | P3: =_xlfn.CONCAT("('",A3,"','",B3,"','",C3,"','",D3,"','",E3,"',",F3,",",G3,",'",H3,"','",J3,"',",K3,",",N3,",",O3,"),") -> ('1a7f70e8-f02d-485e-aa9a-42bb5c4073d5','2025-03-13 06:44:12.673942+00','866dabc4-6501-44d2-a0e5-65da9c45a46e','2025-03-13 06:44:12.673942+00','866dabc4-6501-44d2-a0e5-65da9c45a46e',TRUE,0,'UserIncome','ee7268d6-3012-4918-ad50-df59ac091c9d',250,2,0),
A4: ed158529-1772-4e9d-9b1e-9b5ea4e62424 | B4: 2025-03-13 06:43:53.391525+00 | C4: 866dabc4-6501-44d2-a0e5-65da9c45a46e | D4: 2025-03-13 06:43:53.391525+00 | E4: 866dabc4-6501-44d2-a0e5-65da9c45a46e | F4: TRUE | G4: 0 | H4: UserIncome | J4: 258a7d9f-5fa7-4eae-8d31-bb7f64d35a79 | K4: 270 | N4: 2 | O4: 0 | P4: =_xlfn.CONCAT("('",A4,"','",B4,"','",C4,"','",D4,"','",E4,"',",F4,",",G4,",'",H4,"','",J4,"',",K4,",",N4,",",O4,"),") -> ('ed158529-1772-4e9d-9b1e-9b5ea4e62424','2025-03-13 06:43:53.391525+00','866dabc4-6501-44d2-a0e5-65da9c45a46e','2025-03-13 06:43:53.391525+00','866dabc4-6501-44d2-a0e5-65da9c45a46e',TRUE,0,'UserIncome','258a7d9f-5fa7-4eae-8d31-bb7f64d35a79',270,2,0),
A5: a0980814-1ec8-4151-8293-ed6ebe64a596 | B5: 2025-03-13 06:34:22.149052+00 | C5: 866dabc4-6501-44d2-a0e5-65da9c45a46e | D5: 2025-03-13 06:43:33.754449+00 | E5: 866dabc4-6501-44d2-a0e5-65da9c45a46e | F5: TRUE | G5: 0 | H5: UserIncome | J5: 4875d3e5-9a6d-41c5-b3d5-7b4359c1baad | K5: 288 | N5: 2 | O5: 0 | P5: =_xlfn.CONCAT("('",A5,"','",B5,"','",C5,"','",D5,"','",E5,"',",F5,",",G5,",'",H5,"','",J5,"',",K5,",",N5,",",O5,"),") -> ('a0980814-1ec8-4151-8293-ed6ebe64a596','2025-03-13 06:34:22.149052+00','866dabc4-6501-44d2-a0e5-65da9c45a46e','2025-03-13 06:43:33.754449+00','866dabc4-6501-44d2-a0e5-65da9c45a46e',TRUE,0,'UserIncome','4875d3e5-9a6d-41c5-b3d5-7b4359c1baad',288,2,0),
A6: ec227798-704d-47a5-83f0-c3e303e03477 | B6: 2025-03-13 06:39:46.685407+00 | C6: 866dabc4-6501-44d2-a0e5-65da9c45a46e | D6: 2025-03-13 06:39:46.685407+00 | E6: 866dabc4-6501-44d2-a0e5-65da9c45a46e | F6: TRUE | G6: 0 | H6: UserIncome | J6: 832bd9bf-6d52-4261-8eb0-80c3ca1fa1dd | K6: 450 | N6: 1 | O6: 0 | P6: =_xlfn.CONCAT("('",A6,"','",B6,"','",C6,"','",D6,"','",E6,"',",F6,",",G6,",'",H6,"','",J6,"',",K6,",",N6,",",O6,"),") -> ('ec227798-704d-47a5-83f0-c3e303e03477','2025-03-13 06:39:46.685407+00','866dabc4-6501-44d2-a0e5-65da9c45a46e','2025-03-13 06:39:46.685407+00','866dabc4-6501-44d2-a0e5-65da9c45a46e',TRUE,0,'UserIncome','832bd9bf-6d52-4261-8eb0-80c3ca1fa1dd',450,1,0),
A7: ecf05ebb-806c-447e-b734-d21ddba3e484 | B7: 2025-03-13 06:44:20.488909+00 | C7: 866dabc4-6501-44d2-a0e5-65da9c45a46e | D7: 2025-03-13 06:44:20.488909+00 | E7: 866dabc4-6501-44d2-a0e5-65da9c45a46e | F7: TRUE | G7: 0 | H7: UserIncome | J7: 8090c38f-ca53-4238-810d-811a59e6cc68 | K7: 250 | N7: 2 | O7: 0 | P7: =_xlfn.CONCAT("('",A7,"','",B7,"','",C7,"','",D7,"','",E7,"',",F7,",",G7,",'",H7,"','",J7,"',",K7,",",N7,",",O7,"),") -> ('ecf05ebb-806c-447e-b734-d21ddba3e484','2025-03-13 06:44:20.488909+00','866dabc4-6501-44d2-a0e5-65da9c45a46e','2025-03-13 06:44:20.488909+00','866dabc4-6501-44d2-a0e5-65da9c45a46e',TRUE,0,'UserIncome','8090c38f-ca53-4238-810d-811a59e6cc68',250,2,0),
A8: a109bb70-04c3-448a-9312-b63c96352252 | B8: 2025-03-13 06:42:29.455616+00 | C8: 866dabc4-6501-44d2-a0e5-65da9c45a46e | D8: 2025-03-13 06:42:29.455616+00 | E8: 866dabc4-6501-44d2-a0e5-65da9c45a46e | F8: TRUE | G8: 0 | H8: UserIncome | J8: 83ae307c-cd8c-4564-b0e8-da8d0b3f63fc | K8: 288 | N8: 2 | O8: 0 | P8: =_xlfn.CONCAT("('",A8,"','",B8,"','",C8,"','",D8,"','",E8,"',",F8,",",G8,",'",H8,"','",J8,"',",K8,",",N8,",",O8,"),") -> ('a109bb70-04c3-448a-9312-b63c96352252','2025-03-13 06:42:29.455616+00','866dabc4-6501-44d2-a0e5-65da9c45a46e','2025-03-13 06:42:29.455616+00','866dabc4-6501-44d2-a0e5-65da9c45a46e',TRUE,0,'UserIncome','83ae307c-cd8c-4564-b0e8-da8d0b3f63fc',288,2,0),
A9: bc2e951a-fe6d-420c-80e3-11f7428e872d | B9: 2025-03-13 06:40:04.332113+00 | C9: 866dabc4-6501-44d2-a0e5-65da9c45a46e | D9: 2025-03-13 06:43:21.662104+00 | E9: 866dabc4-6501-44d2-a0e5-65da9c45a46e | F9: TRUE | G9: 0 | H9: UserIncome | J9: ca5037bc-1ffb-4fcb-a5d0-495c3cd5aa99 | K9: 270 | N9: 2 | O9: 0 | P9: =_xlfn.CONCAT("('",A9,"','",B9,"','",C9,"','",D9,"','",E9,"',",F9,",",G9,",'",H9,"','",J9,"',",K9,",",N9,",",O9,"),") -> ('bc2e951a-fe6d-420c-80e3-11f7428e872d','2025-03-13 06:40:04.332113+00','866dabc4-6501-44d2-a0e5-65da9c45a46e','2025-03-13 06:43:21.662104+00','866dabc4-6501-44d2-a0e5-65da9c45a46e',TRUE,0,'UserIncome','ca5037bc-1ffb-4fcb-a5d0-495c3cd5aa99',270,2,0),
A10: 5080a050-ed36-4457-9981-4303362547ed | B10: 2025-03-13 06:40:15.952421+00 | C10: 866dabc4-6501-44d2-a0e5-65da9c45a46e | D10: 2025-03-13 06:43:27.83884+00 | E10: 866dabc4-6501-44d2-a0e5-65da9c45a46e | F10: TRUE | G10: 0 | H10: UserIncome | J10: 6ac9ae0c-53d1-497e-9e7d-3ce976d1f0d8 | K10: 270 | N10: 2 | O10: 0 | P10: =_xlfn.CONCAT("('",A10,"','",B10,"','",C10,"','",D10,"','",E10,"',",F10,",",G10,",'",H10,"','",J10,"',",K10,",",N10,",",O10,"),") -> ('5080a050-ed36-4457-9981-4303362547ed','2025-03-13 06:40:15.952421+00','866dabc4-6501-44d2-a0e5-65da9c45a46e','2025-03-13 06:43:27.83884+00','866dabc4-6501-44d2-a0e5-65da9c45a46e',TRUE,0,'UserIncome','6ac9ae0c-53d1-497e-9e7d-3ce976d1f0d8',270,2,0),
A11: c6052a39-0d46-4c59-ad41-269c25de9559 | B11: 2025-03-13 06:42:29.455616+01 | C11: 866dabc4-6501-44d2-a0e5-65da9c45a46e | D11: 2025-03-13 06:42:29.455616+01 | E11: 866dabc4-6501-44d2-a0e5-65da9c45a46e | F11: TRUE | G11: 0 | H11: UserIncome | J11: eb8ed330-f3ab-4966-993c-2245653e075e | K11: 258 | N11: 2 | O11: 0 | P11: =_xlfn.CONCAT("('",A11,"','",B11,"','",C11,"','",D11,"','",E11,"',",F11,",",G11,",'",H11,"','",J11,"',",K11,",",N11,",",O11,"),") -> ('c6052a39-0d46-4c59-ad41-269c25de9559','2025-03-13 06:42:29.455616+01','866dabc4-6501-44d2-a0e5-65da9c45a46e','2025-03-13 06:42:29.455616+01','866dabc4-6501-44d2-a0e5-65da9c45a46e',TRUE,0,'UserIncome','eb8ed330-f3ab-4966-993c-2245653e075e',258,2,0),
A12: 2fc4e9cf-e05c-4a72-b1b8-b443908c11b2 | B12: 2025-03-13 06:40:04.332113+01 | C12: 866dabc4-6501-44d2-a0e5-65da9c45a46e | D12: 2025-03-13 06:43:21.662104+01 | E12: 866dabc4-6501-44d2-a0e5-65da9c45a46e | F12: TRUE | G12: 0 | H12: UserIncome | J12: ee44cb44-8886-4193-9a02-53fdad80e46e | K12: 249 | N12: 2 | O12: 0 | P12: =_xlfn.CONCAT("('",A12,"','",B12,"','",C12,"','",D12,"','",E12,"',",F12,",",G12,",'",H12,"','",J12,"',",K12,",",N12,",",O12,"),") -> ('2fc4e9cf-e05c-4a72-b1b8-b443908c11b2','2025-03-13 06:40:04.332113+01','866dabc4-6501-44d2-a0e5-65da9c45a46e','2025-03-13 06:43:21.662104+01','866dabc4-6501-44d2-a0e5-65da9c45a46e',TRUE,0,'UserIncome','ee44cb44-8886-4193-9a02-53fdad80e46e',249,2,0),
A13: 8bff6968-5f4b-49be-a180-c8eba9848ddb | B13: 2025-03-13 06:40:15.952421+01 | C13: 866dabc4-6501-44d2-a0e5-65da9c45a46e | D13: 2025-03-13 06:43:27.83884+01 | E13: 866dabc4-6501-44d2-a0e5-65da9c45a46e | F13: TRUE | G13: 0 | H13: UserIncome | J13: 7d26cfab-fb31-41cc-a4ea-29e610568be3 | K13: 240 | N13: 2 | O13: 0 | P13: =_xlfn.CONCAT("('",A13,"','",B13,"','",C13,"','",D13,"','",E13,"',",F13,",",G13,",'",H13,"','",J13,"',",K13,",",N13,",",O13,");") -> ('8bff6968-5f4b-49be-a180-c8eba9848ddb','2025-03-13 06:40:15.952421+01','866dabc4-6501-44d2-a0e5-65da9c45a46e','2025-03-13 06:43:27.83884+01','866dabc4-6501-44d2-a0e5-65da9c45a46e',TRUE,0,'UserIncome','7d26cfab-fb31-41cc-a4ea-29e610568be3',240,2,0);

Sheet Value_Patients (alun)
E1: PID IdentityNo | I1: CoverageScheme
A2: 6505315 | B2: 866dabc4-6501-44d2-a0e5-65da9c45a46e | C2: TRUE | D2: 6505315 | E2: 3100800257727 | F2: แฮร์รี่ พอตเตอร์ | G2: M | H2: 1994-12-23 | I2: -4 | K2: -1 | M2: =_xlfn.CONCAT("(",A2,",'",B2,"',",C2,",",D2,",'",E2,"','",F2,"','",G2,"','",H2,"',",I2,",",K2,"),") -> (6505315,'866dabc4-6501-44d2-a0e5-65da9c45a46e',TRUE,6505315,'3100800257727','แฮร์รี่ พอตเตอร์','M','1994-12-23',-4,-1),
A3: 6455308 | B3: 866dabc4-6501-44d2-a0e5-65da9c45a46e | C3: TRUE | D3: 6455308 | E3: 1250500084692 | F3: เฮอร์ไมโอนี่ เกรนเจอร์ | G3: F | H3: 1995-01-02 | I3: -4 | K3: -1 | M3: =_xlfn.CONCAT("(",A3,",'",B3,"',",C3,",",D3,",'",E3,"','",F3,"','",G3,"','",H3,"',",I3,",",K3,"),") -> (6455308,'866dabc4-6501-44d2-a0e5-65da9c45a46e',TRUE,6455308,'1250500084692','เฮอร์ไมโอนี่ เกรนเจอร์','F','1995-01-02',-4,-1),
A4: 6508733 | B4: 866dabc4-6501-44d2-a0e5-65da9c45a46e | C4: TRUE | D4: 6508733 | E4: 3360100764683 | F4: รอน วีสลีย์ | G4: M | H4: 1994-12-24 | I4: -2 | K4: -1 | M4: =_xlfn.CONCAT("(",A4,",'",B4,"',",C4,",",D4,",'",E4,"','",F4,"','",G4,"','",H4,"',",I4,",",K4,"),") -> (6508733,'866dabc4-6501-44d2-a0e5-65da9c45a46e',TRUE,6508733,'3360100764683','รอน วีสลีย์','M','1994-12-24',-2,-1),
A5: 6512620 | B5: 866dabc4-6501-44d2-a0e5-65da9c45a46e | C5: TRUE | D5: 6512620 | E5: 3251000314521 | F5: จินนี่ วีสลีย์ | G5: F | H5: 1995-01-03 | I5: -2 | K5: -1 | M5: =_xlfn.CONCAT("(",A5,",'",B5,"',",C5,",",D5,",'",E5,"','",F5,"','",G5,"','",H5,"',",I5,",",K5,"),") -> (6512620,'866dabc4-6501-44d2-a0e5-65da9c45a46e',TRUE,6512620,'3251000314521','จินนี่ วีสลีย์','F','1995-01-03',-2,-1),
A6: 6300865 | B6: 866dabc4-6501-44d2-a0e5-65da9c45a46e | C6: TRUE | D6: 6300865 | E6: 3251100436629 | F6: เฟร็ด วีสลีย์ | G6: M | H6: 1994-12-25 | I6: -2 | K6: -1 | M6: =_xlfn.CONCAT("(",A6,",'",B6,"',",C6,",",D6,",'",E6,"','",F6,"','",G6,"','",H6,"',",I6,",",K6,"),") -> (6300865,'866dabc4-6501-44d2-a0e5-65da9c45a46e',TRUE,6300865,'3251100436629','เฟร็ด วีสลีย์','M','1994-12-25',-2,-1),
A7: 6519635 | B7: 866dabc4-6501-44d2-a0e5-65da9c45a46e | C7: TRUE | D7: 6519635 | E7: 3209900248972 | F7: จอร์จ วีสลีย์ | G7: M | H7: 1995-01-04 | I7: -2 | K7: -1 | M7: =_xlfn.CONCAT("(",A7,",'",B7,"',",C7,",",D7,",'",E7,"','",F7,"','",G7,"','",H7,"',",I7,",",K7,"),") -> (6519635,'866dabc4-6501-44d2-a0e5-65da9c45a46e',TRUE,6519635,'3209900248972','จอร์จ วีสลีย์','M','1995-01-04',-2,-1),
A8: 6521515 | B8: 866dabc4-6501-44d2-a0e5-65da9c45a46e | C8: TRUE | D8: 6521515 | E8: 1259700118769 | F8: เพอร์ซี่ วีสลีย์ | G8: M | H8: 1994-12-26 | I8: -2 | K8: -1 | M8: =_xlfn.CONCAT("(",A8,",'",B8,"',",C8,",",D8,",'",E8,"','",F8,"','",G8,"','",H8,"',",I8,",",K8,"),") -> (6521515,'866dabc4-6501-44d2-a0e5-65da9c45a46e',TRUE,6521515,'1259700118769','เพอร์ซี่ วีสลีย์','M','1994-12-26',-2,-1),
A9: 6521637 | B9: 866dabc4-6501-44d2-a0e5-65da9c45a46e | C9: TRUE | D9: 6521637 | E9: 3200101356962 | F9: อาเธอร์ วีสลีย์ | G9: M | H9: 1995-01-05 | I9: -2 | K9: -1 | M9: =_xlfn.CONCAT("(",A9,",'",B9,"',",C9,",",D9,",'",E9,"','",F9,"','",G9,"','",H9,"',",I9,",",K9,"),") -> (6521637,'866dabc4-6501-44d2-a0e5-65da9c45a46e',TRUE,6521637,'3200101356962','อาเธอร์ วีสลีย์','M','1995-01-05',-2,-1),
A10: 49082/54 | B10: 866dabc4-6501-44d2-a0e5-65da9c45a46e | C10: TRUE | D10: 49082/54 | E10: 3140100082339 | F10: มอลลี่ วีสลีย์ | G10: F | H10: 1994-12-27 | I10: -2 | K10: -1 | M10: =_xlfn.CONCAT("(",A10,",'",B10,"',",C10,",",D10,",'",E10,"','",F10,"','",G10,"','",H10,"',",I10,",",K10,"),") -> (49082/54,'866dabc4-6501-44d2-a0e5-65da9c45a46e',TRUE,49082/54,'3140100082339','มอลลี่ วีสลีย์','F','1994-12-27',-2,-1),
A11: 6602502 | B11: 866dabc4-6501-44d2-a0e5-65da9c45a46e | C11: TRUE | D11: 6602502 | E11: 2270100001500 | F11: เนวิลล์ ลองบัตท่อม | G11: M | H11: 1995-01-06 | I11: -4 | K11: -1 | M11: =_xlfn.CONCAT("(",A11,",'",B11,"',",C11,",",D11,",'",E11,"','",F11,"','",G11,"','",H11,"',",I11,",",K11,"),") -> (6602502,'866dabc4-6501-44d2-a0e5-65da9c45a46e',TRUE,6602502,'2270100001500','เนวิลล์ ลองบัตท่อม','M','1995-01-06',-4,-1),
A12: 6603132 | B12: 866dabc4-6501-44d2-a0e5-65da9c45a46e | C12: TRUE | D12: 6603132 | E12: 5301700031064 | F12: ลูน่า เลิฟกู๊ด | G12: F | H12: 1994-12-28 | I12: -4 | K12: -1 | M12: =_xlfn.CONCAT("(",A12,",'",B12,"',",C12,",",D12,",'",E12,"','",F12,"','",G12,"','",H12,"',",I12,",",K12,"),") -> (6603132,'866dabc4-6501-44d2-a0e5-65da9c45a46e',TRUE,6603132,'5301700031064','ลูน่า เลิฟกู๊ด','F','1994-12-28',-4,-1),
A13: 5333974 | B13: 866dabc4-6501-44d2-a0e5-65da9c45a46e | C13: TRUE | D13: 5333974 | E13: 3200700272537 | F13: โช แชง | G13: F | H13: 1995-01-07 | I13: -4 | K13: -1 | M13: =_xlfn.CONCAT("(",A13,",'",B13,"',",C13,",",D13,",'",E13,"','",F13,"','",G13,"','",H13,"',",I13,",",K13,"),") -> (5333974,'866dabc4-6501-44d2-a0e5-65da9c45a46e',TRUE,5333974,'3200700272537','โช แชง','F','1995-01-07',-4,-1),
A14: 213860 | B14: 866dabc4-6501-44d2-a0e5-65da9c45a46e | C14: TRUE | D14: 213860 | E14: 3710500143011 | F14: ดัดลีย์ เดอร์สลีย์ | G14: M | H14: 1994-12-29 | I14: -4 | K14: -1 | M14: =_xlfn.CONCAT("(",A14,",'",B14,"',",C14,",",D14,",'",E14,"','",F14,"','",G14,"','",H14,"',",I14,",",K14,"),") -> (213860,'866dabc4-6501-44d2-a0e5-65da9c45a46e',TRUE,213860,'3710500143011','ดัดลีย์ เดอร์สลีย์','M','1994-12-29',-4,-1),
A15: 48324 | B15: 866dabc4-6501-44d2-a0e5-65da9c45a46e | C15: TRUE | D15: 48324 | E15: 3259900149575 | F15: เวอร์นอน เดอร์สลีย์ | G15: M | H15: 1995-01-08 | I15: -4 | K15: -1 | M15: =_xlfn.CONCAT("(",A15,",'",B15,"',",C15,",",D15,",'",E15,"','",F15,"','",G15,"','",H15,"',",I15,",",K15,"),") -> (48324,'866dabc4-6501-44d2-a0e5-65da9c45a46e',TRUE,48324,'3259900149575','เวอร์นอน เดอร์สลีย์','M','1995-01-08',-4,-1),
A16: 670001117 | B16: 866dabc4-6501-44d2-a0e5-65da9c45a46e | C16: TRUE | D16: 670001117 | E16: 3250100583388 | F16: เพทูเนีย เดอร์สลีย์ | G16: F | H16: 2012-01-18 | I16: -4 | K16: -1 | M16: =_xlfn.CONCAT("(",A16,",'",B16,"',",C16,",",D16,",'",E16,"','",F16,"','",G16,"','",H16,"',",I16,",",K16,"),") -> (670001117,'866dabc4-6501-44d2-a0e5-65da9c45a46e',TRUE,670001117,'3250100583388','เพทูเนีย เดอร์สลีย์','F','2012-01-18',-4,-1),
A17: 6701952 | B17: 866dabc4-6501-44d2-a0e5-65da9c45a46e | C17: TRUE | D17: 6701952 | E17: 3251000141325 | F17: ลอร์ดโวลเดอมอร์ | G17: M | H17: 1994-12-23 | I17: -4 | K17: 1 | M17: =_xlfn.CONCAT("(",A17,",'",B17,"',",C17,",",D17,",'",E17,"','",F17,"','",G17,"','",H17,"',",I17,",",K17,"),") -> (6701952,'866dabc4-6501-44d2-a0e5-65da9c45a46e',TRUE,6701952,'3251000141325','ลอร์ดโวลเดอมอร์','M','1994-12-23',-4,1),
A18: 6702221 | B18: 866dabc4-6501-44d2-a0e5-65da9c45a46e | C18: TRUE | D18: 6702221 | E18: 1250400165950 | F18: เบลลาทริกซ์ เลสแตรงจ์ | G18: F | H18: 1995-01-02 | I18: -4 | K18: 1 | M18: =_xlfn.CONCAT("(",A18,",'",B18,"',",C18,",",D18,",'",E18,"','",F18,"','",G18,"','",H18,"',",I18,",",K18,"),") -> (6702221,'866dabc4-6501-44d2-a0e5-65da9c45a46e',TRUE,6702221,'1250400165950','เบลลาทริกซ์ เลสแตรงจ์','F','1995-01-02',-4,1),
A19: 67030106 | B19: 866dabc4-6501-44d2-a0e5-65da9c45a46e | C19: TRUE | D19: 67030106 | E19: 5270500000980 | F19: ลูเซียส มัลฟอย | G19: M | H19: 1994-12-24 | I19: -4 | K19: 1 | M19: =_xlfn.CONCAT("(",A19,",'",B19,"',",C19,",",D19,",'",E19,"','",F19,"','",G19,"','",H19,"',",I19,",",K19,"),") -> (67030106,'866dabc4-6501-44d2-a0e5-65da9c45a46e',TRUE,67030106,'5270500000980','ลูเซียส มัลฟอย','M','1994-12-24',-4,1),
A20: 184706 | B20: 866dabc4-6501-44d2-a0e5-65da9c45a46e | C20: TRUE | D20: 184706 | E20: 3250500209131 | F20: เดรโก มัลฟอย | G20: M | H20: 1995-01-03 | I20: -4 | K20: 1 | M20: =_xlfn.CONCAT("(",A20,",'",B20,"',",C20,",",D20,",'",E20,"','",F20,"','",G20,"','",H20,"',",I20,",",K20,"),") -> (184706,'866dabc4-6501-44d2-a0e5-65da9c45a46e',TRUE,184706,'3250500209131','เดรโก มัลฟอย','M','1995-01-03',-4,1),
A21: 530323 | B21: 866dabc4-6501-44d2-a0e5-65da9c45a46e | C21: TRUE | D21: 530323 | E21: 3310800115203 | F21: นาร์ซิสซา มัลฟอย | G21: F | H21: 1994-12-25 | I21: -4 | K21: 1 | M21: =_xlfn.CONCAT("(",A21,",'",B21,"',",C21,",",D21,",'",E21,"','",F21,"','",G21,"','",H21,"',",I21,",",K21,"),") -> (530323,'866dabc4-6501-44d2-a0e5-65da9c45a46e',TRUE,530323,'3310800115203','นาร์ซิสซา มัลฟอย','F','1994-12-25',-4,1),
A22: 6706476 | B22: 866dabc4-6501-44d2-a0e5-65da9c45a46e | C22: TRUE | D22: 6706476 | E22: 1250500092211 | F22: ปีเตอร์ เพ็ตติกรูว์ | G22: M | H22: 1995-01-04 | I22: -4 | K22: 1 | M22: =_xlfn.CONCAT("(",A22,",'",B22,"',",C22,",",D22,",'",E22,"','",F22,"','",G22,"','",H22,"',",I22,",",K22,"),") -> (6706476,'866dabc4-6501-44d2-a0e5-65da9c45a46e',TRUE,6706476,'1250500092211','ปีเตอร์ เพ็ตติกรูว์','M','1995-01-04',-4,1),
... A30: 6411508 | B30: 866dabc4-6501-44d2-a0e5-65da9c45a46e | C30: TRUE | D30: 6411508 | E30: 5130199018677 | F30: นิมฟาดอร่า ท็องก์ส | G30: F | H30: 2012-01-18 | I30: -3 | K30: -1 | M30: =_xlfn.CONCAT("(",A30,",'",B30,"',",C30,",",D30,",'",E30,"','",F30,"','",G30,"','",H30,"',",I30,",",K30,"),") -> (6411508,'866dabc4-6501-44d2-a0e5-65da9c45a46e',TRUE,6411508,'5130199018677','นิมฟาดอร่า ท็องก์ส','F','2012-01-18',-3,-1),
A31: 6802740 | B31: 866dabc4-6501-44d2-a0e5-65da9c45a46e | C31: TRUE | D31: 6802740 | E31: 3259700104471 | F31: มาด-อาย มู้ดดี้ | G31: M | H31: 1994-12-23 | I31: -3 | K31: -1 | M31: =_xlfn.CONCAT("(",A31,",'",B31,"',",C31,",",D31,",'",E31,"','",F31,"','",G31,"','",H31,"',",I31,",",K31,");") -> (6802740,'866dabc4-6501-44d2-a0e5-65da9c45a46e',TRUE,6802740,'3259700104471','มาด-อาย มู้ดดี้','M','1994-12-23',-3,-1);

Sheet Value_DialysisPrescriptions
A1: Id | B1: Created | C1: CreatedBy | D1: Updated | E1: UpdatedBy | F1: IsActive | G1: PatientId | H1: Temporary | I1: Mode | J1: HdfType | K1: SubstituteVolume | L1: IvSupplementVolume | M1: IvSupplementPosition | N1: DryWeight | O1: ExcessFluidRemovalAmount | P1: BloodFlow | Q1: BloodTransfusion | R1: ExtraFluid | S1: Duration | T1: Frequency | U1: Anticoagulant | V1: AcPerSession | W1: InitialAmount | X1: MaintainAmount | Y1: ReasonForRefraining | Z1: AcPerSessionMl | AA1: InitialAmountMl | AB1: MaintainAmountMl | AC1: DialysateK | AD1: DialysateCa | AE1: HCO3 | AF1: Na | AG1: DialysateTemperature | AH1: DialysateFlowRate | AI1: BloodAccessRoute | AJ1: ANeedleCC | AK1: VNeedleCC | AL1: ArterialNeedle | AM1: VenousNeedle | AN1: Dialyzer | AO1: DialyzerSurfaceArea | AP1: AvgDialyzerReuse | AQ1: DialysisNurse | AR1: Note | AS1: DialyzerId
A2: b25379c3-dc0d-4791-b222-a6354fa53b5d | B2: 2025-03-16 03:00:05.236692+00 | C2: 866dabc4-6501-44d2-a0e5-65da9c45a46e | D2: 2025-03-16 03:00:05.236692+00 | E2: 866dabc4-6501-44d2-a0e5-65da9c45a46e | F2: TRUE | G2: 101 | H2: FALSE | I2: 3 | N2: 34 | P2: 23 | S2: 4:05:00 | AU2: =_xlfn.CONCAT("('",A2,"','",B2,"','",C2,"','",D2,"','",E2,"',",F2,",",G2,",",H2,",",I2,",",N2,",",P2,",'",S2,"'),") -> ('b25379c3-dc0d-4791-b222-a6354fa53b5d','2025-03-16 03:00:05.236692+00','866dabc4-6501-44d2-a0e5-65da9c45a46e','2025-03-16 03:00:05.236692+00','866dabc4-6501-44d2-a0e5-65da9c45a46e',TRUE,101,FALSE,3,34,23,'4:05:00'),
A3: 3e8b2a4d-f06c-4b74-873a-6a1f56e9b5df | B3: 2025-03-16 03:00:05.236692+00 | C3: 866dabc4-6501-44d2-a0e5-65da9c45a46e | D3: 2025-03-16 03:00:05.236692+00 | E3: 866dabc4-6501-44d2-a0e5-65da9c45a46e | F3: TRUE | G3: 102 | H3: FALSE | I3: 3 | N3: 34 | P3: 23 | S3: 4:05:00 | AU3: =_xlfn.CONCAT("('",A3,"','",B3,"','",C3,"','",D3,"','",E3,"',",F3,",",G3,",",H3,",",I3,",",N3,",",P3,",'",S3,"'),") -> ('3e8b2a4d-f06c-4b74-873a-6a1f56e9b5df','2025-03-16 03:00:05.236692+00','866dabc4-6501-44d2-a0e5-65da9c45a46e','2025-03-16 03:00:05.236692+00','866dabc4-6501-44d2-a0e5-65da9c45a46e',TRUE,102,FALSE,3,34,23,'4:05:00'),
A4: f9b4d3c2-7a59-4b1a-89b0-14a3c04bfae2 | B4: 2025-03-16 03:00:05.236692+00 | C4: 866dabc4-6501-44d2-a0e5-65da9c45a46e | D4: 2025-03-16 03:00:05.236692+00 | E4: 866dabc4-6501-44d2-a0e5-65da9c45a46e | F4: TRUE | G4: 103 | H4: FALSE | I4: 3 | N4: 34 | P4: 23 | S4: 4:05:00 | AU4: =_xlfn.CONCAT("('",A4,"','",B4,"','",C4,"','",D4,"','",E4,"',",F4,",",G4,",",H4,",",I4,",",N4,",",P4,",'",S4,"'),") -> ('f9b4d3c2-7a59-4b1a-89b0-14a3c04bfae2','2025-03-16 03:00:05.236692+00','866dabc4-6501-44d2-a0e5-65da9c45a46e','2025-03-16 03:00:05.236692+00','866dabc4-6501-44d2-a0e5-65da9c45a46e',TRUE,103,FALSE,3,34,23,'4:05:00'),
A5: 2c4a8f97-3d71-40e7-a8c4-28bcbfc23b35 | B5: 2025-03-16 03:00:05.236692+00 | C5: 866dabc4-6501-44d2-a0e5-65da9c45a46e | D5: 2025-03-16 03:00:05.236692+00 | E5: 866dabc4-6501-44d2-a0e5-65da9c45a46e | F5: TRUE | G5: 104 | H5: FALSE | I5: 3 | N5: 34 | P5: 23 | S5: 4:05:00 | AU5: =_xlfn.CONCAT("('",A5,"','",B5,"','",C5,"','",D5,"','",E5,"',",F5,",",G5,",",H5,",",I5,",",N5,",",P5,",'",S5,"'),") -> ('2c4a8f97-3d71-40e7-a8c4-28bcbfc23b35','2025-03-16 03:00:05.236692+00','866dabc4-6501-44d2-a0e5-65da9c45a46e','2025-03-16 03:00:05.236692+00','866dabc4-6501-44d2-a0e5-65da9c45a46e',TRUE,104,FALSE,3,34,23,'4:05:00'),
A6: 7b152e30-0c4f-41d1-a637-84ebad5a8579 | B6: 2025-03-16 03:00:05.236692+00 | C6: 866dabc4-6501-44d2-a0e5-65da9c45a46e | D6: 2025-03-16 03:00:05.236692+00 | E6: 866dabc4-6501-44d2-a0e5-65da9c45a46e | F6: TRUE | G6: 105 | H6: FALSE | I6: 3 | N6: 34 | P6: 23 | S6: 4:05:00 | AU6: =_xlfn.CONCAT("('",A6,"','",B6,"','",C6,"','",D6,"','",E6,"',",F6,",",G6,",",H6,",",I6,",",N6,",",P6,",'",S6,"'),") -> ('7b152e30-0c4f-41d1-a637-84ebad5a8579','2025-03-16 03:00:05.236692+00','866dabc4-6501-44d2-a0e5-65da9c45a46e','2025-03-16 03:00:05.236692+00','866dabc4-6501-44d2-a0e5-65da9c45a46e',TRUE,105,FALSE,3,34,23,'4:05:00'),
A7: 94d93217-19d0-43c5-b0da-8c4a3741c771 | B7: 2025-03-16 03:00:05.236692+00 | C7: 866dabc4-6501-44d2-a0e5-65da9c45a46e | D7: 2025-03-16 03:00:05.236692+00 | E7: 866dabc4-6501-44d2-a0e5-65da9c45a46e | F7: TRUE | G7: 106 | H7: FALSE | I7: 3 | N7: 34 | P7: 23 | S7: 4:05:00 | AU7: =_xlfn.CONCAT("('",A7,"','",B7,"','",C7,"','",D7,"','",E7,"',",F7,",",G7,",",H7,",",I7,",",N7,",",P7,",'",S7,"'),") -> ('94d93217-19d0-43c5-b0da-8c4a3741c771','2025-03-16 03:00:05.236692+00','866dabc4-6501-44d2-a0e5-65da9c45a46e','2025-03-16 03:00:05.236692+00','866dabc4-6501-44d2-a0e5-65da9c45a46e',TRUE,106,FALSE,3,34,23,'4:05:00'),
A8: c3e452d6-6f1e-4b9d-8c68-5f24d0e73945 | B8: 2025-03-16 03:00:05.236692+00 | C8: 866dabc4-6501-44d2-a0e5-65da9c45a46e | D8: 2025-03-16 03:00:05.236692+00 | E8: 866dabc4-6501-44d2-a0e5-65da9c45a46e | F8: TRUE | G8: 107 | H8: FALSE | I8: 3 | N8: 34 | P8: 23 | S8: 4:05:00 | AU8: =_xlfn.CONCAT("('",A8,"','",B8,"','",C8,"','",D8,"','",E8,"',",F8,",",G8,",",H8,",",I8,",",N8,",",P8,",'",S8,"'),") -> ('c3e452d6-6f1e-4b9d-8c68-5f24d0e73945','2025-03-16 03:00:05.236692+00','866dabc4-6501-44d2-a0e5-65da9c45a46e','2025-03-16 03:00:05.236692+00','866dabc4-6501-44d2-a0e5-65da9c45a46e',TRUE,107,FALSE,3,34,23,'4:05:00'),
A9: 67f8239d-a7ea-4efb-b14c-6b8c8e64bcd4 | B9: 2025-03-16 03:00:05.236692+00 | C9: 866dabc4-6501-44d2-a0e5-65da9c45a46e | D9: 2025-03-16 03:00:05.236692+00 | E9: 866dabc4-6501-44d2-a0e5-65da9c45a46e | F9: TRUE | G9: 108 | H9: FALSE | I9: 3 | N9: 34 | P9: 23 | S9: 4:05:00 | AU9: =_xlfn.CONCAT("('",A9,"','",B9,"','",C9,"','",D9,"','",E9,"',",F9,",",G9,",",H9,",",I9,",",N9,",",P9,",'",S9,"'),") -> ('67f8239d-a7ea-4efb-b14c-6b8c8e64bcd4','2025-03-16 03:00:05.236692+00','866dabc4-6501-44d2-a0e5-65da9c45a46e','2025-03-16 03:00:05.236692+00','866dabc4-6501-44d2-a0e5-65da9c45a46e',TRUE,108,FALSE,3,34,23,'4:05:00'),
A10: d5294cb9-3161-4149-8f02-89f3f9f7d6b4 | B10: 2025-03-16 03:00:05.236692+00 | C10: 866dabc4-6501-44d2-a0e5-65da9c45a46e | D10: 2025-03-16 03:00:05.236692+00 | E10: 866dabc4-6501-44d2-a0e5-65da9c45a46e | F10: TRUE | G10: 109 | H10: FALSE | I10: 3 | N10: 34 | P10: 23 | S10: 4:05:00 | AU10: =_xlfn.CONCAT("('",A10,"','",B10,"','",C10,"','",D10,"','",E10,"',",F10,",",G10,",",H10,",",I10,",",N10,",",P10,",'",S10,"'),") -> ('d5294cb9-3161-4149-8f02-89f3f9f7d6b4','2025-03-16 03:00:05.236692+00','866dabc4-6501-44d2-a0e5-65da9c45a46e','2025-03-16 03:00:05.236692+00','866dabc4-6501-44d2-a0e5-65da9c45a46e',TRUE,109,FALSE,3,34,23,'4:05:00'),
A11: b5c2a478-fb4e-43d5-b601-c426fb8a906c | B11: 2025-03-16 03:00:05.236692+00 | C11: 866dabc4-6501-44d2-a0e5-65da9c45a46e | D11: 2025-03-16 03:00:05.236692+00 | E11: 866dabc4-6501-44d2-a0e5-65da9c45a46e | F11: TRUE | G11: 110 | H11: FALSE | I11: 3 | N11: 34 | P11: 23 | S11: 4:05:00 | AU11: =_xlfn.CONCAT("('",A11,"','",B11,"','",C11,"','",D11,"','",E11,"',",F11,",",G11,",",H11,",",I11,",",N11,",",P11,",'",S11,"'),") -> ('b5c2a478-fb4e-43d5-b601-c426fb8a906c','2025-03-16 03:00:05.236692+00','866dabc4-6501-44d2-a0e5-65da9c45a46e','2025-03-16 03:00:05.236692+00','866dabc4-6501-44d2-a0e5-65da9c45a46e',TRUE,110,FALSE,3,34,23,'4:05:00'),
A12: 1d5e0a8b-76f7-46cd-9e47-2eb7f98f47e2 | B12: 2025-03-16 03:00:05.236692+00 | C12: 866dabc4-6501-44d2-a0e5-65da9c45a46e | D12: 2025-03-16 03:00:05.236692+00 | E12: 866dabc4-6501-44d2-a0e5-65da9c45a46e | F12: TRUE | G12: 111 | H12: FALSE | I12: 3 | N12: 34 | P12: 23 | S12: 4:05:00 | AU12: =_xlfn.CONCAT("('",A12,"','",B12,"','",C12,"','",D12,"','",E12,"',",F12,",",G12,",",H12,",",I12,",",N12,",",P12,",'",S12,"'),") -> ('1d5e0a8b-76f7-46cd-9e47-2eb7f98f47e2','2025-03-16 03:00:05.236692+00','866dabc4-6501-44d2-a0e5-65da9c45a46e','2025-03-16 03:00:05.236692+00','866dabc4-6501-44d2-a0e5-65da9c45a46e',TRUE,111,FALSE,3,34,23,'4:05:00'),
A13: a09c56df-c477-4a3f-a905-7392d3f6cb4f | B13: 2025-03-16 03:00:05.236692+00 | C13: 866dabc4-6501-44d2-a0e5-65da9c45a46e | D13: 2025-03-16 03:00:05.236692+00 | E13: 866dabc4-6501-44d2-a0e5-65da9c45a46e | F13: TRUE | G13: 112 | H13: FALSE | I13: 3 | N13: 34 | P13: 23 | S13: 4:05:00 | AU13: =_xlfn.CONCAT("('",A13,"','",B13,"','",C13,"','",D13,"','",E13,"',",F13,",",G13,",",H13,",",I13,",",N13,",",P13,",'",S13,"'),") -> ('a09c56df-c477-4a3f-a905-7392d3f6cb4f','2025-03-16 03:00:05.236692+00','866dabc4-6501-44d2-a0e5-65da9c45a46e','2025-03-16 03:00:05.236692+00','866dabc4-6501-44d2-a0e5-65da9c45a46e',TRUE,112,FALSE,3,34,23,'4:05:00'),
... A33: 8f4d23a7-6e91-4c5b-b2c9-71d5f38a0e58 | B33: 2025-03-16 03:00:05.236692+00 | C33: 866dabc4-6501-44d2-a0e5-65da9c45a46e | D33: 2025-03-16 03:00:05.236692+00 | E33: 866dabc4-6501-44d2-a0e5-65da9c45a46e | F33: TRUE | G33: 132 | H33: FALSE | I33: 3 | N33: 34 | P33: 23 | S33: 4:05:00 | AU33: =_xlfn.CONCAT("('",A33,"','",B33,"','",C33,"','",D33,"','",E33,"',",F33,",",G33,",",H33,",",I33,",",N33,",",P33,",'",S33,"'),") -> ('8f4d23a7-6e91-4c5b-b2c9-71d5f38a0e58','2025-03-16 03:00:05.236692+00','866dabc4-6501-44d2-a0e5-65da9c45a46e','2025-03-16 03:00:05.236692+00','866dabc4-6501-44d2-a0e5-65da9c45a46e',TRUE,132,FALSE,3,34,23,'4:05:00'),
A34: a3b72e91-5d48-4c9f-81f7-2d0c6b4a5e39 | B34: 2025-03-16 03:00:05.236692+00 | C34: 866dabc4-6501-44d2-a0e5-65da9c45a46e | D34: 2025-03-16 03:00:05.236692+00 | E34: 866dabc4-6501-44d2-a0e5-65da9c45a46e | F34: TRUE | G34: 133 | H34: FALSE | I34: 3 | N34: 34 | P34: 23 | S34: 4:05:00 | AU34: =_xlfn.CONCAT("('",A34,"','",B34,"','",C34,"','",D34,"','",E34,"',",F34,",",G34,",",H34,",",I34,",",N34,",",P34,",'",S34,"');") -> ('a3b72e91-5d48-4c9f-81f7-2d0c6b4a5e39','2025-03-16 03:00:05.236692+00','866dabc4-6501-44d2-a0e5-65da9c45a46e','2025-03-16 03:00:05.236692+00','866dabc4-6501-44d2-a0e5-65da9c45a46e',TRUE,133,FALSE,3,34,23,'4:05:00');

Sheet medecine
A1: Id | B1: Created | C1: CreatedBy | D1: Updated | E1: UpdatedBy | F1: IsActive | G1: CategoryId | H1: UsageWays | I1: DoseAmount | J1: MedType | K1: Name | L1: Code | M1: PieceUnit | N1: Barcode | O1: Note | P1: Image
A2: 1 | C2: 866dabc4-6501-44d2-a0e5-65da9c45a46e | F2: TRUE | H2: 0 | J2: 0 | K2: BINOCRIT | Q2: =_xlfn.CONCAT("(",A2,",'",C2,"',",F2,",",H2,",",J2,",'",K2,"'),") -> (1,'866dabc4-6501-44d2-a0e5-65da9c45a46e',TRUE,0,0,'BINOCRIT'),
A3: 2 | C3: 866dabc4-6501-44d2-a0e5-65da9c45a46e | F3: TRUE | H3: 0 | J3: 0 | K3: EPOTIV | Q3: =_xlfn.CONCAT("(",A3,",'",C3,"',",F3,",",H3,",",J3,",'",K3,"'),") -> (2,'866dabc4-6501-44d2-a0e5-65da9c45a46e',TRUE,0,0,'EPOTIV'),
A4: 3 | C4: 866dabc4-6501-44d2-a0e5-65da9c45a46e | F4: TRUE | H4: 0 | J4: 0 | K4: EPREX | Q4: =_xlfn.CONCAT("(",A4,",'",C4,"',",F4,",",H4,",",J4,",'",K4,"'),") -> (3,'866dabc4-6501-44d2-a0e5-65da9c45a46e',TRUE,0,0,'EPREX'),
A5: 4 | C5: 866dabc4-6501-44d2-a0e5-65da9c45a46e | F5: TRUE | H5: 0 | J5: 0 | K5: ESPOGEN (LIFE Sci) | Q5: =_xlfn.CONCAT("(",A5,",'",C5,"',",F5,",",H5,",",J5,",'",K5,"'),") -> (4,'866dabc4-6501-44d2-a0e5-65da9c45a46e',TRUE,0,0,'ESPOGEN (LIFE Sci)'),
A6: 5 | C6: 866dabc4-6501-44d2-a0e5-65da9c45a46e | F6: TRUE | H6: 0 | J6: 0 | K6: HEMAX | Q6: =_xlfn.CONCAT("(",A6,",'",C6,"',",F6,",",H6,",",J6,",'",K6,"'),") -> (5,'866dabc4-6501-44d2-a0e5-65da9c45a46e',TRUE,0,0,'HEMAX'),
A7: 6 | C7: 866dabc4-6501-44d2-a0e5-65da9c45a46e | F7: TRUE | H7: 0 | J7: 0 | K7: RECORMON | Q7: =_xlfn.CONCAT("(",A7,",'",C7,"',",F7,",",H7,",",J7,",'",K7,"');") -> (6,'866dabc4-6501-44d2-a0e5-65da9c45a46e',TRUE,0,0,'RECORMON');
Q9: (1,'866dabc4-6501-44d2-a0e5-65da9c45a46e',TRUE,0,0,'BINOCRIT'),
Q10: (2,'866dabc4-6501-44d2-a0e5-65da9c45a46e',TRUE,0,0,'EPOTIV'),
Q11: (3,'866dabc4-6501-44d2-a0e5-65da9c45a46e',TRUE,0,0,'EPREX'),
Q12: (4,'866dabc4-6501-44d2-a0e5-65da9c45a46e',TRUE,0,0,'ESPOGEN (LIFE Sci)'),
Q13: (5,'866dabc4-6501-44d2-a0e5-65da9c45a46e',TRUE,0,0,'HEMAX'),
Q14: (6,'866dabc4-6501-44d2-a0e5-65da9c45a46e',TRUE,0,0,'RECORMON');

Sheet Value_DiaPrescrip (alun)
A1: Id | B1: Created | C1: CreatedBy | D1: Updated | E1: UpdatedBy | F1: IsActive | G1: PatientId | H1: Temporary | I1: Mode | J1: HdfType | K1: SubstituteVolume | L1: IvSupplementVolume | M1: IvSupplementPosition | N1: DryWeight | O1: ExcessFluidRemovalAmount | P1: BloodFlow | Q1: BloodTransfusion | R1: ExtraFluid | S1: Duration | T1: Frequency | U1: Anticoagulant | V1: AcPerSession | W1: InitialAmount | X1: MaintainAmount | Y1: ReasonForRefraining | Z1: AcPerSessionMl | AA1: InitialAmountMl | AB1: MaintainAmountMl | AC1: DialysateK | AD1: DialysateCa | AE1: HCO3 | AF1: Na | AG1: DialysateTemperature | AH1: DialysateFlowRate | AI1: BloodAccessRoute | AJ1: ANeedleCC | AK1: VNeedleCC | AL1: ArterialNeedle | AM1: VenousNeedle | AN1: Dialyzer | AO1: DialyzerSurfaceArea | AP1: AvgDialyzerReuse | AQ1: DialysisNurse | AR1: Note | AS1: DialyzerId
A2: b25379c3-dc0d-4791-b222-a6354fa53b5d | B2: 2025-06-17 03:00:05.236692+00 | C2: 866dabc4-6501-44d2-a0e5-65da9c45a46e | D2: 2025-06-17 03:00:05.236692+00 | E2: 866dabc4-6501-44d2-a0e5-65da9c45a46e | F2: TRUE | G2: 6505315 | H2: FALSE | I2: 3 | N2: 34 | P2: 23 | S2: 4:05:00 | AU2: =_xlfn.CONCAT("('",A2,"','",B2,"','",C2,"','",D2,"','",E2,"',",F2,",",G2,",",H2,",",I2,",",N2,",",P2,",'",S2,"'),") -> ('b25379c3-dc0d-4791-b222-a6354fa53b5d','2025-06-17 03:00:05.236692+00','866dabc4-6501-44d2-a0e5-65da9c45a46e','2025-06-17 03:00:05.236692+00','866dabc4-6501-44d2-a0e5-65da9c45a46e',TRUE,6505315,FALSE,3,34,23,'4:05:00'),
A3: 3e8b2a4d-f06c-4b74-873a-6a1f56e9b5df | B3: 2025-06-17 03:00:05.236692+00 | C3: 866dabc4-6501-44d2-a0e5-65da9c45a46e | D3: 2025-06-17 03:00:05.236692+00 | E3: 866dabc4-6501-44d2-a0e5-65da9c45a46e | F3: TRUE | G3: 6455308 | H3: FALSE | I3: 3 | N3: 34 | P3: 23 | S3: 4:05:00 | AU3: =_xlfn.CONCAT("('",A3,"','",B3,"','",C3,"','",D3,"','",E3,"',",F3,",",G3,",",H3,",",I3,",",N3,",",P3,",'",S3,"'),") -> ('3e8b2a4d-f06c-4b74-873a-6a1f56e9b5df','2025-06-17 03:00:05.236692+00','866dabc4-6501-44d2-a0e5-65da9c45a46e','2025-06-17 03:00:05.236692+00','866dabc4-6501-44d2-a0e5-65da9c45a46e',TRUE,6455308,FALSE,3,34,23,'4:05:00'),
A4: f9b4d3c2-7a59-4b1a-89b0-14a3c04bfae2 | B4: 2025-06-17 03:00:05.236692+00 | C4: 866dabc4-6501-44d2-a0e5-65da9c45a46e | D4: 2025-06-17 03:00:05.236692+00 | E4: 866dabc4-6501-44d2-a0e5-65da9c45a46e | F4: TRUE | G4: 6508733 | H4: FALSE | I4: 3 | N4: 34 | P4: 23 | S4: 4:05:00 | AU4: =_xlfn.CONCAT("('",A4,"','",B4,"','",C4,"','",D4,"','",E4,"',",F4,",",G4,",",H4,",",I4,",",N4,",",P4,",'",S4,"'),") -> ('f9b4d3c2-7a59-4b1a-89b0-14a3c04bfae2','2025-06-17 03:00:05.236692+00','866dabc4-6501-44d2-a0e5-65da9c45a46e','2025-06-17 03:00:05.236692+00','866dabc4-6501-44d2-a0e5-65da9c45a46e',TRUE,6508733,FALSE,3,34,23,'4:05:00'),
A5: 2c4a8f97-3d71-40e7-a8c4-28bcbfc23b35 | B5: 2025-06-17 03:00:05.236692+00 | C5: 866dabc4-6501-44d2-a0e5-65da9c45a46e | D5: 2025-06-17 03:00:05.236692+00 | E5: 866dabc4-6501-44d2-a0e5-65da9c45a46e | F5: TRUE | G5: 6512620 | H5: FALSE | I5: 3 | N5: 34 | P5: 23 | S5: 4:05:00 | AU5: =_xlfn.CONCAT("('",A5,"','",B5,"','",C5,"','",D5,"','",E5,"',",F5,",",G5,",",H5,",",I5,",",N5,",",P5,",'",S5,"'),") -> ('2c4a8f97-3d71-40e7-a8c4-28bcbfc23b35','2025-06-17 03:00:05.236692+00','866dabc4-6501-44d2-a0e5-65da9c45a46e','2025-06-17 03:00:05.236692+00','866dabc4-6501-44d2-a0e5-65da9c45a46e',TRUE,6512620,FALSE,3,34,23,'4:05:00'),
A6: 7b152e30-0c4f-41d1-a637-84ebad5a8579 | B6: 2025-06-17 03:00:05.236692+00 | C6: 866dabc4-6501-44d2-a0e5-65da9c45a46e | D6: 2025-06-17 03:00:05.236692+00 | E6: 866dabc4-6501-44d2-a0e5-65da9c45a46e | F6: TRUE | G6: 6300865 | H6: FALSE | I6: 3 | N6: 34 | P6: 23 | S6: 4:05:00 | AU6: =_xlfn.CONCAT("('",A6,"','",B6,"','",C6,"','",D6,"','",E6,"',",F6,",",G6,",",H6,",",I6,",",N6,",",P6,",'",S6,"'),") -> ('7b152e30-0c4f-41d1-a637-84ebad5a8579','2025-06-17 03:00:05.236692+00','866dabc4-6501-44d2-a0e5-65da9c45a46e','2025-06-17 03:00:05.236692+00','866dabc4-6501-44d2-a0e5-65da9c45a46e',TRUE,6300865,FALSE,3,34,23,'4:05:00'),
A7: 94d93217-19d0-43c5-b0da-8c4a3741c771 | B7: 2025-06-17 03:00:05.236692+00 | C7: 866dabc4-6501-44d2-a0e5-65da9c45a46e | D7: 2025-06-17 03:00:05.236692+00 | E7: 866dabc4-6501-44d2-a0e5-65da9c45a46e | F7: TRUE | G7: 6519635 | H7: FALSE | I7: 3 | N7: 34 | P7: 23 | S7: 4:05:00 | AU7: =_xlfn.CONCAT("('",A7,"','",B7,"','",C7,"','",D7,"','",E7,"',",F7,",",G7,",",H7,",",I7,",",N7,",",P7,",'",S7,"'),") -> ('94d93217-19d0-43c5-b0da-8c4a3741c771','2025-06-17 03:00:05.236692+00','866dabc4-6501-44d2-a0e5-65da9c45a46e','2025-06-17 03:00:05.236692+00','866dabc4-6501-44d2-a0e5-65da9c45a46e',TRUE,6519635,FALSE,3,34,23,'4:05:00'),
A8: c3e452d6-6f1e-4b9d-8c68-5f24d0e73945 | B8: 2025-06-17 03:00:05.236692+00 | C8: 866dabc4-6501-44d2-a0e5-65da9c45a46e | D8: 2025-06-17 03:00:05.236692+00 | E8: 866dabc4-6501-44d2-a0e5-65da9c45a46e | F8: TRUE | G8: 6521515 | H8: FALSE | I8: 3 | N8: 34 | P8: 23 | S8: 4:05:00 | AU8: =_xlfn.CONCAT("('",A8,"','",B8,"','",C8,"','",D8,"','",E8,"',",F8,",",G8,",",H8,",",I8,",",N8,",",P8,",'",S8,"'),") -> ('c3e452d6-6f1e-4b9d-8c68-5f24d0e73945','2025-06-17 03:00:05.236692+00','866dabc4-6501-44d2-a0e5-65da9c45a46e','2025-06-17 03:00:05.236692+00','866dabc4-6501-44d2-a0e5-65da9c45a46e',TRUE,6521515,FALSE,3,34,23,'4:05:00'),
A9: 67f8239d-a7ea-4efb-b14c-6b8c8e64bcd4 | B9: 2025-06-17 03:00:05.236692+00 | C9: 866dabc4-6501-44d2-a0e5-65da9c45a46e | D9: 2025-06-17 03:00:05.236692+00 | E9: 866dabc4-6501-44d2-a0e5-65da9c45a46e | F9: TRUE | G9: 6521637 | H9: FALSE | I9: 3 | N9: 34 | P9: 23 | S9: 4:05:00 | AU9: =_xlfn.CONCAT("('",A9,"','",B9,"','",C9,"','",D9,"','",E9,"',",F9,",",G9,",",H9,",",I9,",",N9,",",P9,",'",S9,"'),") -> ('67f8239d-a7ea-4efb-b14c-6b8c8e64bcd4','2025-06-17 03:00:05.236692+00','866dabc4-6501-44d2-a0e5-65da9c45a46e','2025-06-17 03:00:05.236692+00','866dabc4-6501-44d2-a0e5-65da9c45a46e',TRUE,6521637,FALSE,3,34,23,'4:05:00'),
A10: d5294cb9-3161-4149-8f02-89f3f9f7d6b4 | B10: 2025-06-17 03:00:05.236692+00 | C10: 866dabc4-6501-44d2-a0e5-65da9c45a46e | D10: 2025-06-17 03:00:05.236692+00 | E10: 866dabc4-6501-44d2-a0e5-65da9c45a46e | F10: TRUE | G10: 49082/54 | H10: FALSE | I10: 3 | N10: 34 | P10: 23 | S10: 4:05:00 | AU10: =_xlfn.CONCAT("('",A10,"','",B10,"','",C10,"','",D10,"','",E10,"',",F10,",",G10,",",H10,",",I10,",",N10,",",P10,",'",S10,"'),") -> ('d5294cb9-3161-4149-8f02-89f3f9f7d6b4','2025-06-17 03:00:05.236692+00','866dabc4-6501-44d2-a0e5-65da9c45a46e','2025-06-17 03:00:05.236692+00','866dabc4-6501-44d2-a0e5-65da9c45a46e',TRUE,49082/54,FALSE,3,34,23,'4:05:00'),
A11: b5c2a478-fb4e-43d5-b601-c426fb8a906c | B11: 2025-06-17 03:00:05.236692+00 | C11: 866dabc4-6501-44d2-a0e5-65da9c45a46e | D11: 2025-06-17 03:00:05.236692+00 | E11: 866dabc4-6501-44d2-a0e5-65da9c45a46e | F11: TRUE | G11: 6602502 | H11: FALSE | I11: 3 | N11: 34 | P11: 23 | S11: 4:05:00 | AU11: =_xlfn.CONCAT("('",A11,"','",B11,"','",C11,"','",D11,"','",E11,"',",F11,",",G11,",",H11,",",I11,",",N11,",",P11,",'",S11,"'),") -> ('b5c2a478-fb4e-43d5-b601-c426fb8a906c','2025-06-17 03:00:05.236692+00','866dabc4-6501-44d2-a0e5-65da9c45a46e','2025-06-17 03:00:05.236692+00','866dabc4-6501-44d2-a0e5-65da9c45a46e',TRUE,6602502,FALSE,3,34,23,'4:05:00'),
A12: 1d5e0a8b-76f7-46cd-9e47-2eb7f98f47e2 | B12: 2025-06-17 03:00:05.236692+00 | C12: 866dabc4-6501-44d2-a0e5-65da9c45a46e | D12: 2025-06-17 03:00:05.236692+00 | E12: 866dabc4-6501-44d2-a0e5-65da9c45a46e | F12: TRUE | G12: 6603132 | H12: FALSE | I12: 3 | N12: 34 | P12: 23 | S12: 4:05:00 | AU12: =_xlfn.CONCAT("('",A12,"','",B12,"','",C12,"','",D12,"','",E12,"',",F12,",",G12,",",H12,",",I12,",",N12,",",P12,",'",S12,"'),") -> ('1d5e0a8b-76f7-46cd-9e47-2eb7f98f47e2','2025-06-17 03:00:05.236692+00','866dabc4-6501-44d2-a0e5-65da9c45a46e','2025-06-17 03:00:05.236692+00','866dabc4-6501-44d2-a0e5-65da9c45a46e',TRUE,6603132,FALSE,3,34,23,'4:05:00'),
A13: a09c56df-c477-4a3f-a905-7392d3f6cb4f | B13: 2025-06-17 03:00:05.236692+00 | C13: 866dabc4-6501-44d2-a0e5-65da9c45a46e | D13: 2025-06-17 03:00:05.236692+00 | E13: 866dabc4-6501-44d2-a0e5-65da9c45a46e | F13: TRUE | G13: 5333974 | H13: FALSE | I13: 3 | N13: 34 | P13: 23 | S13: 4:05:00 | AU13: =_xlfn.CONCAT("('",A13,"','",B13,"','",C13,"','",D13,"','",E13,"',",F13,",",G13,",",H13,",",I13,",",N13,",",P13,",'",S13,"'),") -> ('a09c56df-c477-4a3f-a905-7392d3f6cb4f','2025-06-17 03:00:05.236692+00','866dabc4-6501-44d2-a0e5-65da9c45a46e','2025-06-17 03:00:05.236692+00','866dabc4-6501-44d2-a0e5-65da9c45a46e',TRUE,5333974,FALSE,3,34,23,'4:05:00'),
A14: 5c1f407e-46b8-4092-8be1-22708b3e3d3b | B14: 2025-06-17 03:00:05.236692+00 | C14: 866dabc4-6501-44d2-a0e5-65da9c45a46e | D14: 2025-06-17 03:00:05.236692+00 | E14: 866dabc4-6501-44d2-a0e5-65da9c45a46e | F14: TRUE | G14: 213860 | H14: FALSE | I14: 3 | N14: 34 | P14: 23 | S14: 4:05:00 | AU14: =_xlfn.CONCAT("('",A14,"','",B14,"','",C14,"','",D14,"','",E14,"',",F14,",",G14,",",H14,",",I14,",",N14,",",P14,",'",S14,"'),") -> ('5c1f407e-46b8-4092-8be1-22708b3e3d3b','2025-06-17 03:00:05.236692+00','866dabc4-6501-44d2-a0e5-65da9c45a46e','2025-06-17 03:00:05.236692+00','866dabc4-6501-44d2-a0e5-65da9c45a46e',TRUE,213860,FALSE,3,34,23,'4:05:00'),
A15: e3b9f574-66f6-4021-a26d-7cb5b9f77d3b | B15: 2025-06-17 03:00:05.236692+00 | C15: 866dabc4-6501-44d2-a0e5-65da9c45a46e | D15: 2025-06-17 03:00:05.236692+00 | E15: 866dabc4-6501-44d2-a0e5-65da9c45a46e | F15: TRUE | G15: 48324 | H15: FALSE | I15: 3 | N15: 34 | P15: 23 | S15: 4:05:00 | AU15: =_xlfn.CONCAT("('",A15,"','",B15,"','",C15,"','",D15,"','",E15,"',",F15,",",G15,",",H15,",",I15,",",N15,",",P15,",'",S15,"'),") -> ('e3b9f574-66f6-4021-a26d-7cb5b9f77d3b','2025-06-17 03:00:05.236692+00','866dabc4-6501-44d2-a0e5-65da9c45a46e','2025-06-17 03:00:05.236692+00','866dabc4-6501-44d2-a0e5-65da9c45a46e',TRUE,48324,FALSE,3,34,23,'4:05:00'),
A16: 33a8c5f4-d2fc-4f67-8a43-2fb2c9d826d4 | B16: 2025-06-17 03:00:05.236692+00 | C16: 866dabc4-6501-44d2-a0e5-65da9c45a46e | D16: 2025-06-17 03:00:05.236692+00 | E16: 866dabc4-6501-44d2-a0e5-65da9c45a46e | F16: TRUE | G16: 670001117 | H16: FALSE | I16: 3 | N16: 34 | P16: 23 | S16: 4:05:00 | AU16: =_xlfn.CONCAT("('",A16,"','",B16,"','",C16,"','",D16,"','",E16,"',",F16,",",G16,",",H16,",",I16,",",N16,",",P16,",'",S16,"'),") -> ('33a8c5f4-d2fc-4f67-8a43-2fb2c9d826d4','2025-06-17 03:00:05.236692+00','866dabc4-6501-44d2-a0e5-65da9c45a46e','2025-06-17 03:00:05.236692+00','866dabc4-6501-44d2-a0e5-65da9c45a46e',TRUE,670001117,FALSE,3,34,23,'4:05:00'),
A17: b7ef23c9-043e-4a47-a68f-7123f9a27584 | B17: 2025-06-17 03:00:05.236692+00 | C17: 866dabc4-6501-44d2-a0e5-65da9c45a46e | D17: 2025-06-17 03:00:05.236692+00 | E17: 866dabc4-6501-44d2-a0e5-65da9c45a46e | F17: TRUE | G17: 6701952 | H17: FALSE | I17: 3 | N17: 34 | P17: 23 | S17: 4:05:00 | AU17: =_xlfn.CONCAT("('",A17,"','",B17,"','",C17,"','",D17,"','",E17,"',",F17,",",G17,",",H17,",",I17,",",N17,",",P17,",'",S17,"'),") -> ('b7ef23c9-043e-4a47-a68f-7123f9a27584','2025-06-17 03:00:05.236692+00','866dabc4-6501-44d2-a0e5-65da9c45a46e','2025-06-17 03:00:05.236692+00','866dabc4-6501-44d2-a0e5-65da9c45a46e',TRUE,6701952,FALSE,3,34,23,'4:05:00'),
A18: 728de94d-48b4-4cf3-a10b-0f75cde7b7d6 | B18: 2025-06-17 03:00:05.236692+00 | C18: 866dabc4-6501-44d2-a0e5-65da9c45a46e | D18: 2025-06-17 03:00:05.236692+00 | E18: 866dabc4-6501-44d2-a0e5-65da9c45a46e | F18: TRUE | G18: 6702221 | H18: FALSE | I18: 3 | N18: 34 | P18: 23 | S18: 4:05:00 | AU18: =_xlfn.CONCAT("('",A18,"','",B18,"','",C18,"','",D18,"','",E18,"',",F18,",",G18,",",H18,",",I18,",",N18,",",P18,",'",S18,"'),") -> ('728de94d-48b4-4cf3-a10b-0f75cde7b7d6','2025-06-17 03:00:05.236692+00','866dabc4-6501-44d2-a0e5-65da9c45a46e','2025-06-17 03:00:05.236692+00','866dabc4-6501-44d2-a0e5-65da9c45a46e',TRUE,6702221,FALSE,3,34,23,'4:05:00'),
A19: 196c3eb2-62ff-4568-9311-7cd24b1e5d92 | B19: 2025-06-17 03:00:05.236692+00 | C19: 866dabc4-6501-44d2-a0e5-65da9c45a46e | D19: 2025-06-17 03:00:05.236692+00 | E19: 866dabc4-6501-44d2-a0e5-65da9c45a46e | F19: TRUE | G19: 67030106 | H19: FALSE | I19: 3 | N19: 34 | P19: 23 | S19: 4:05:00 | AU19: =_xlfn.CONCAT("('",A19,"','",B19,"','",C19,"','",D19,"','",E19,"',",F19,",",G19,",",H19,",",I19,",",N19,",",P19,",'",S19,"'),") -> ('196c3eb2-62ff-4568-9311-7cd24b1e5d92','2025-06-17 03:00:05.236692+00','866dabc4-6501-44d2-a0e5-65da9c45a46e','2025-06-17 03:00:05.236692+00','866dabc4-6501-44d2-a0e5-65da9c45a46e',TRUE,67030106,FALSE,3,34,23,'4:05:00'),
A20: c1bfa478-7ea9-44cd-8fd3-1a4d9f0c8e37 | B20: 2025-06-17 03:00:05.236692+00 | C20: 866dabc4-6501-44d2-a0e5-65da9c45a46e | D20: 2025-06-17 03:00:05.236692+00 | E20: 866dabc4-6501-44d2-a0e5-65da9c45a46e | F20: TRUE | G20: 184706 | H20: FALSE | I20: 3 | N20: 34 | P20: 23 | S20: 4:05:00 | AU20: =_xlfn.CONCAT("('",A20,"','",B20,"','",C20,"','",D20,"','",E20,"',",F20,",",G20,",",H20,",",I20,",",N20,",",P20,",'",S20,"'),") -> ('c1bfa478-7ea9-44cd-8fd3-1a4d9f0c8e37','2025-06-17 03:00:05.236692+00','866dabc4-6501-44d2-a0e5-65da9c45a46e','2025-06-17 03:00:05.236692+00','866dabc4-6501-44d2-a0e5-65da9c45a46e',TRUE,184706,FALSE,3,34,23,'4:05:00'),
A21: 2e0f95c1-8bda-40d9-8497-5fd5cdce7284 | B21: 2025-06-17 03:00:05.236692+00 | C21: 866dabc4-6501-44d2-a0e5-65da9c45a46e | D21: 2025-06-17 03:00:05.236692+00 | E21: 866dabc4-6501-44d2-a0e5-65da9c45a46e | F21: TRUE | G21: 530323 | H21: FALSE | I21: 3 | N21: 34 | P21: 23 | S21: 4:05:00 | AU21: =_xlfn.CONCAT("('",A21,"','",B21,"','",C21,"','",D21,"','",E21,"',",F21,",",G21,",",H21,",",I21,",",N21,",",P21,",'",S21,"'),") -> ('2e0f95c1-8bda-40d9-8497-5fd5cdce7284','2025-06-17 03:00:05.236692+00','866dabc4-6501-44d2-a0e5-65da9c45a46e','2025-06-17 03:00:05.236692+00','866dabc4-6501-44d2-a0e5-65da9c45a46e',TRUE,530323,FALSE,3,34,23,'4:05:00'),
A22: 0f34b8c9-5293-4c45-b2a4-8e2d7f8dcb36 | B22: 2025-06-17 03:00:05.236692+00 | C22: 866dabc4-6501-44d2-a0e5-65da9c45a46e | D22: 2025-06-17 03:00:05.236692+00 | E22: 866dabc4-6501-44d2-a0e5-65da9c45a46e | F22: TRUE | G22: 6706476 | H22: FALSE | I22: 3 | N22: 34 | P22: 23 | S22: 4:05:00 | AU22: =_xlfn.CONCAT("('",A22,"','",B22,"','",C22,"','",D22,"','",E22,"',",F22,",",G22,",",H22,",",I22,",",N22,",",P22,",'",S22,"'),") -> ('0f34b8c9-5293-4c45-b2a4-8e2d7f8dcb36','2025-06-17 03:00:05.236692+00','866dabc4-6501-44d2-a0e5-65da9c45a46e','2025-06-17 03:00:05.236692+00','866dabc4-6501-44d2-a0e5-65da9c45a46e',TRUE,6706476,FALSE,3,34,23,'4:05:00'),
... A31: 5e8b1a3c-9f47-4d2b-b8e7-a31c5d7f2b65 | B31: 2025-06-17 03:00:05.236692+00 | C31: 866dabc4-6501-44d2-a0e5-65da9c45a46e | D31: 2025-06-17 03:00:05.236692+00 | E31: 866dabc4-6501-44d2-a0e5-65da9c45a46e | F31: TRUE | G31: 6802740 | H31: FALSE | I31: 3 | N31: 34 | P31: 23 | S31: 4:05:00 | AU31: =_xlfn.CONCAT("('",A31,"','",B31,"','",C31,"','",D31,"','",E31,"',",F31,",",G31,",",H31,",",I31,",",N31,",",P31,",'",S31,"'),") -> ('5e8b1a3c-9f47-4d2b-b8e7-a31c5d7f2b65','2025-06-17 03:00:05.236692+00','866dabc4-6501-44d2-a0e5-65da9c45a46e','2025-06-17 03:00:05.236692+00','866dabc4-6501-44d2-a0e5-65da9c45a46e',TRUE,6802740,FALSE,3,34,23,'4:05:00'),
AU33: ('b25379c3-dc0d-4791-b222-a6354fa53b5d','2025-06-17 03:00:05.236692+00','866dabc4-6501-44d2-a0e5-65da9c45a46e','2025-06-17 03:00:05.236692+00','866dabc4-6501-44d2-a0e5-65da9c45a46e',TRUE,6505315,FALSE,3,34,23,'4:05:00'),
